<?xml version="1.0"?>
<mujoco model="simple_hinge">
  <compiler angle="radian"/>
  <option timestep="0.002" gravity="0 0 -9.81"/>

  <worldbody>
    <body name="link1" pos="0 0 0">
      <!-- Base link: small cube -->
      <geom name="geom1" type="box" size="0.05 0.05 0.05" rgba="0.8 0.2 0.2 1"/>

      <!-- Moving link: elongated box so rotation is clearly visible -->
      <body name="link2" pos="0 0 0.1">
        <joint name="hinge_joint" type="hinge" axis="1 0 0"/>
        <geom name="geom2" type="box" size="0.02 0.02 0.1" rgba="0.2 0.2 0.8 1"/>
      </body>
    </body>
  </worldbody>

  <actuator>
    <motor name="hinge_motor" joint="hinge_joint" ctrlrange="-1 1" gear="100"/>
  </actuator>

</mujoco>